[2021-08-09 05:48:56,438: INFO/MainProcess] Connected to amqp://guest:**@broker:5672//
[2021-08-09 05:48:56,453: INFO/MainProcess] mingle: searching for neighbors
[2021-08-09 05:48:57,493: INFO/MainProcess] mingle: all alone
[2021-08-09 05:48:57,518: INFO/MainProcess] celery@1cc9202b2f2a ready.
[2021-08-09 05:48:57,520: INFO/MainProcess] Task ml.predict_ocr[38a22bdc-53f0-4395-bae3-18d7fc786f8d] received
[2021-08-09 05:48:57,521: INFO/MainProcess] Task ml.predict_ocr[556de1a2-10b7-484b-a905-0475052cdb4e] received
[2021-08-09 05:48:57,684: ERROR/ForkPoolWorker-2] Task ml.predict_ocr[556de1a2-10b7-484b-a905-0475052cdb4e] raised unexpected: TypeError('__init__() takes 5 positional arguments but 6 were given')
Traceback (most recent call last):
  File "/usr/local/lib/python3.9/site-packages/celery/app/trace.py", line 450, in trace_task
    R = retval = fun(*args, **kwargs)
  File "/usr/local/lib/python3.9/site-packages/celery/app/trace.py", line 731, in __protected_call__
    return self.run(*args, **kwargs)
  File "/app/worker/celery.py", line 32, in predict_ocr
    ocr = OcrModel(path_to_checkpoint=MODEL_PATH)
  File "/app/worker/ml/model.py", line 10, in __init__
    self.model = self._load_model_from_path(path_to_checkpoint)
  File "/app/worker/ml/model.py", line 15, in _load_model_from_path
    return TextRecognition(path_to_checkpoint=path)
  File "/app/worker/ml/recognition.py", line 14, in __init__
    self.detector = Predictor(self.config)
  File "/app/worker/ml/predictor.py", line 13, in __init__
    model, vocab = build_model(config)
  File "/app/worker/ml/translate.py", line 112, in build_model
    model = VietOCR(len(vocab),
TypeError: __init__() takes 5 positional arguments but 6 were given
[2021-08-09 05:48:57,684: ERROR/ForkPoolWorker-1] Task ml.predict_ocr[38a22bdc-53f0-4395-bae3-18d7fc786f8d] raised unexpected: TypeError('__init__() takes 5 positional arguments but 6 were given')
Traceback (most recent call last):
  File "/usr/local/lib/python3.9/site-packages/celery/app/trace.py", line 450, in trace_task
    R = retval = fun(*args, **kwargs)
  File "/usr/local/lib/python3.9/site-packages/celery/app/trace.py", line 731, in __protected_call__
    return self.run(*args, **kwargs)
  File "/app/worker/celery.py", line 32, in predict_ocr
    ocr = OcrModel(path_to_checkpoint=MODEL_PATH)
  File "/app/worker/ml/model.py", line 10, in __init__
    self.model = self._load_model_from_path(path_to_checkpoint)
  File "/app/worker/ml/model.py", line 15, in _load_model_from_path
    return TextRecognition(path_to_checkpoint=path)
  File "/app/worker/ml/recognition.py", line 14, in __init__
    self.detector = Predictor(self.config)
  File "/app/worker/ml/predictor.py", line 13, in __init__
    model, vocab = build_model(config)
  File "/app/worker/ml/translate.py", line 112, in build_model
    model = VietOCR(len(vocab),
TypeError: __init__() takes 5 positional arguments but 6 were given
[2021-08-09 05:49:11,493: INFO/MainProcess] Task ml.predict_ocr[29863297-3416-454e-b1ae-a45491f60cc3] received
[2021-08-09 05:49:11,533: ERROR/ForkPoolWorker-1] Task ml.predict_ocr[29863297-3416-454e-b1ae-a45491f60cc3] raised unexpected: TypeError('__init__() takes 5 positional arguments but 6 were given')
Traceback (most recent call last):
  File "/usr/local/lib/python3.9/site-packages/celery/app/trace.py", line 450, in trace_task
    R = retval = fun(*args, **kwargs)
  File "/usr/local/lib/python3.9/site-packages/celery/app/trace.py", line 731, in __protected_call__
    return self.run(*args, **kwargs)
  File "/app/worker/celery.py", line 32, in predict_ocr
    ocr = OcrModel(path_to_checkpoint=MODEL_PATH)
  File "/app/worker/ml/model.py", line 10, in __init__
    self.model = self._load_model_from_path(path_to_checkpoint)
  File "/app/worker/ml/model.py", line 15, in _load_model_from_path
    return TextRecognition(path_to_checkpoint=path)
  File "/app/worker/ml/recognition.py", line 14, in __init__
    self.detector = Predictor(self.config)
  File "/app/worker/ml/predictor.py", line 13, in __init__
    model, vocab = build_model(config)
  File "/app/worker/ml/translate.py", line 112, in build_model
    model = VietOCR(len(vocab),
TypeError: __init__() takes 5 positional arguments but 6 were given
[2021-08-09 06:02:43,540: INFO/MainProcess] Connected to amqp://guest:**@broker:5672//
[2021-08-09 06:02:43,555: INFO/MainProcess] mingle: searching for neighbors
[2021-08-09 06:02:44,602: INFO/MainProcess] mingle: all alone
[2021-08-09 06:02:44,646: INFO/MainProcess] celery@1cc9202b2f2a ready.
